<?xml version="1.0"?>
<robot xmlns:xacro="http://www.ros.org/wiki/xacro">

<xacro:macro name="upperarm" params="name parent_link *origin">


    <!--Properties-->
    <xacro:property name = "arm_length" value = "1"/>
    <xacro:property name = "arm_radius" value = "0.05"/>

    <!--Joint Definition-->
    <joint name = "${name}_joint" type = "revolute">
        <parent link="${parent_link}"/>
        <child link="${name}_link"/>
        <xacro:insert_block name = "origin"/>
        <axis xyz = "0 -1 0"/>
        <limit lower = "${-pi}" upper = "${pi}" velocity = "100" effort = "100"/>
    </joint>

    <!--Link Definition-->
    <link name = "upper_arm_link">
        <visual>
            <origin xyz = "0 0 0" rpy = "0 ${pi/2} 0"/>
            <geometry>
                <cylinder length = "${arm_length}" radius = "${arm_radius}"/>
            </geometry>
            <xacro:insert_block name="material_pink"/>
        </visual>
        <collision>
            <origin xyz = "0 0 0" rpy = "0 ${pi/2} 0"/>
            <geometry>
                <cylinder length = "${arm_length}" radius = "${arm_radius}"/>
            </geometry>
        </collision>
        <xacro:inertial_cylinder_with_pose mass = "1.0" length = "${arm_length}" radius = "${arm_radius}">
            <origin xyz = "0 0 0" rpy = "0 ${pi/2} 0"/>
        </xacro:inertial_cylinder_with_pose>
    </link>

</xacro:macro>   
</robot>