<?xml version='1.0'?>
<robot xmlns:xacro='http://www.ros.org/wiki/xacro'>

    <xacro:include filename='wheel.urdf.xacro'/>

    <xacro:macro name='wheel_with_servo' params='name parent_link *origin *axis'>

        <xacro:property name='servo_link_name'  value='${name}_servo'/>
        <xacro:property name='servo_joint_name' value='${servo_link_name}_joint'/>

        <xacro:property name='material_block'>
            <xacro:insert_block name='material_red'/>
        </xacro:property>

        <joint name='${servo_joint_name}' type='continuous'>
            <parent link='${parent_link}'/>
            <child link='${servo_link_name}'/>
            <xacro:insert_block name='origin'/>
            <axis xyz='0 0 -1'/>
        </joint>

        <link name='${servo_link_name}'>
            <visual>
                <origin xyz='0 0 0'/>
                <geometry>
                    <cylinder length='${servo_width}' radius='${servo_radius}'/>
                </geometry>
                <xacro:insert_block name='material_block'/>
            </visual>
            <collision>
                <origin xyz='0 0 0'/>
                <geometry>
                    <cylinder length='${servo_width}' radius='${servo_radius}'/>
                </geometry>
            </collision>
            <xacro:inertial_cylinder mass='${servo_mass}' radius='${servo_radius}' length='${servo_width}'/>
        </link>

        <ros2_control name='${servo_joint_name}' type='system'>
            <hardware>
                <plugin>gz_ros2_control/GazeboSimSystem</plugin>
            </hardware>
            <joint name='${servo_joint_name}'>
                <command_interface name='position'/>
            </joint>
        </ros2_control>

        <xacro:wheel name='${name}' parent_link='${servo_link_name}'>
            <origin xyz='0 0 ${-servo_height}' rpy='${-pi/2} 0 0'/>
            <xacro:insert_block name='axis'/>
        </xacro:wheel>

    </xacro:macro>   
</robot>
    